#VRML_SIM R2025a utf8

EXTERNPROTO "https://raw.githubusercontent.com/cyberbotics/webots/R2025a/projects/objects/backgrounds/protos/TexturedBackground.proto"
EXTERNPROTO "https://raw.githubusercontent.com/cyberbotics/webots/R2025a/projects/objects/backgrounds/protos/TexturedBackgroundLight.proto"
EXTERNPROTO "https://raw.githubusercontent.com/cyberbotics/webots/R2025a/projects/objects/floors/protos/RectangleArena.proto"
EXTERNPROTO "https://raw.githubusercontent.com/cyberbotics/webots/R2025a/projects/appearances/protos/BrushedAluminium.proto"

WorldInfo {
  title "TEST_ZONE"
  optimalThreadCount 2
}
Viewpoint {
  orientation 5.690661719460839e-15 -3.929251807589748e-17 1 3.518296326795384
  position 28.305438438329794 11.291795720738289 7.223963424013854
  exposure 2
  bloomThreshold 27
}
TexturedBackground {
  texture "stadium"
  skyColor [
    1 1 1
  ]
}
TexturedBackgroundLight {
  texture "stadium"
  luminosity 0
}
RectangleArena {
  floorSize 100 100
  floorTileSize 5 5
  wallThickness 1
  wallHeight 10
  wallAppearance BrushedAluminium {
    IBLStrength 0.6
  }
}
Robot {
  translation -0.012019787745559314 0.012033522573910566 5.75544125174637
  rotation -0.1960071136569288 -0.026487336025464894 0.9802446798764857 2.5330439188108807e-05
  children [
    LED {
      translation -3 0 1
      rotation 0 1 0 0
      children [
        PointLight {
          attenuation 0 0.05 0
          color 0 0 0
          intensity 5
          on FALSE
          radius 500
          castShadows TRUE
        }
        Shape {
          appearance PBRAppearance {
            transparency 0.5
            roughness 1
            IBLStrength 0.5
            emissiveColor 1 1 1
          }
          geometry DEF led_shape Capsule {
            height 0.1
            radius 0.1
            subdivision 36
          }
        }
      ]
      name "LED_0"
      boundingObject USE led_shape
      physics Physics {
        density -1
        mass 1e-05
        centerOfMass [
          0 0 0
        ]
        inertiaMatrix [
          1.2100000000000003e-05 1.2100000000000003e-05 4.6e-06
          0 0 0
        ]
      }
    }
    LED {
      translation 3 0 1
      rotation 0 1 0 0
      children [
        PointLight {
          attenuation 0 0.05 0
          color 0 0 0
          intensity 5
          on FALSE
          radius 500
          castShadows TRUE
        }
        Shape {
          appearance PBRAppearance {
            transparency 0.5
            roughness 1
            IBLStrength 0.5
            emissiveColor 1 1 1
          }
          geometry DEF led_shape Capsule {
            height 0.1
            radius 0.1
            subdivision 36
          }
        }
      ]
      name "LED_1"
      boundingObject USE led_shape
      physics Physics {
        density -1
        mass 1e-05
        centerOfMass [
          0 0 0
        ]
        inertiaMatrix [
          1.2100000000000003e-05 1.2100000000000003e-05 4.6e-06
          0 0 0
        ]
      }
    }
    DEF HINGE_RR HingeJoint {
      jointParameters HingeJointParameters {
        position -0.00027425261763663563
        anchor 0 -0.8 0.5
        minStop -2
        maxStop 2
      }
      device [
        RotationalMotor {
          name "MOTOR_RR1"
          controlPID 2 0 0.5
          maxTorque 5000
        }
      ]
      endPoint Solid {
        translation -2.500000000000012 -1.9998628285642157 1.0003290843334183
        rotation -1 0 0 0.00027425261686815405
        children [
          SliderJoint {
            jointParameters JointParameters {
              position 8.326584589823938e-06
              axis 0 -2.3 -1.22
              minStop -75
              maxStop 1
            }
            device [
              LinearMotor {
                name "MOTOR_SRR"
                controlPID 2 0 0.5
                maxForce 5000
              }
            ]
            endPoint Solid {
              translation 0 -1.7334200681840581 -0.06859673181937
              rotation 1 0 0 0.5
              children [
                DEF PLACE_HOLDER HingeJoint {
                  jointParameters HingeJointParameters {
                    position 0.9999999736683645
                    axis 0 0 1
                    anchor 0 -1 1
                  }
                  device [
                    DEF WHEEL_R RotationalMotor {
                      name "WHEEL_4"
                      maxVelocity 100
                      maxTorque 100
                    }
                  ]
                  endPoint DEF WHEEL_ Solid {
                    translation 0 -1 0.6500000000000001
                    rotation 0 0 0.9999999999999999 0.9999999736683646
                    children [
                      Propeller {
                        shaftAxis 0 0 1
                        centerOfThrust 0 0 1
                        thrustConstants 1 10
                        torqueConstants 0 0
                        device RotationalMotor {
                          name "PROP_4"
                          maxTorque 100
                        }
                        fastHelix Solid {
                          children [
                            DEF WHEEL Shape {
                              appearance PBRAppearance {
                                baseColor 0 0 0
                                roughness 1
                                metalness 0
                              }
                              geometry Cylinder {
                                height 0.3
                                radius 2
                                subdivision 72
                              }
                            }
                          ]
                          boundingObject USE WHEEL
                        }
                      }
                      DEF WHEEL Shape {
                        appearance PBRAppearance {
                          baseColor 0 0 0
                          roughness 1
                          metalness 0
                        }
                        geometry Cylinder {
                          height 0.3
                          radius 2
                          subdivision 72
                        }
                      }
                    ]
                    boundingObject USE WHEEL
                    physics Physics {
                      density -1
                      mass 0.01
                      centerOfMass [
                        0 0 0
                      ]
                      inertiaMatrix [
                        0.010075 0.010075 0.02
                        0 0 0
                      ]
                      damping Damping {
                      }
                    }
                  }
                }
                DEF ARM2 Shape {
                  appearance PBRAppearance {
                    baseColor 0.333333 0 1
                    roughness 1
                    metalness 0.1
                    IBLStrength 0.5
                  }
                  geometry Box {
                    size 1.25 4 1
                  }
                }
              ]
              boundingObject USE ARM2
              physics Physics {
                density -1
                mass 0.3
                centerOfMass [
                  0 0 0
                ]
                inertiaMatrix [
                  1.0625 0.16015625 1.09765625
                  0 0 0
                ]
              }
            }
          }
          DEF ARM_1 Shape {
            appearance PBRAppearance {
              baseColor 1 0.960784 0.529412
              roughness 1
              IBLStrength 0.5
            }
            geometry DEF ARM_ Box {
              size 1 3 1
            }
          }
        ]
        name "solid(3)"
        boundingObject USE ARM_1
        physics Physics {
          density -1
          mass 0.2
          centerOfMass [
            0 0 0
          ]
          inertiaMatrix [
            2500 500 2500
            0 0 0
          ]
        }
      }
    }
    DEF HINGE_FR HingeJoint {
      jointParameters HingeJointParameters {
        position -0.00027425237295944214
        anchor 0 -0.8 0.5
        minStop -2
        maxStop 2
      }
      device [
        RotationalMotor {
          name "MOTOR_FR1"
          controlPID 2 0 0.5
          maxTorque 5000
        }
      ]
      endPoint Solid {
        translation 2.5000000000000138 -1.9998628286866365 1.0003290840398353
        rotation -1 0 0 0.000274252372358178
        children [
          SliderJoint {
            jointParameters JointParameters {
              position 8.326584548634663e-06
              axis 0 -2.3 -1.22
              minStop -75
              maxStop 1
            }
            device [
              LinearMotor {
                name "MOTOR_SFR"
                controlPID 2 0 0.5
                maxForce 5000
              }
            ]
            endPoint Solid {
              translation 0 -1.7334200681834893 -0.06859673181906815
              rotation 1 0 0 0.5
              children [
                DEF PLACE_HOLDER HingeJoint {
                  jointParameters HingeJointParameters {
                    position 3.9999999736683503
                    axis 0 0 1
                    anchor 0 -1 1
                  }
                  device [
                    DEF WHEEL_R RotationalMotor {
                      name "WHEEL_3"
                      maxVelocity 100
                      maxTorque 100
                    }
                  ]
                  endPoint DEF WHEEL_ Solid {
                    translation 0 -1 0.6499999999999999
                    rotation 0 0 1 3.9999999736683503
                    children [
                      Propeller {
                        shaftAxis 0 0 1
                        centerOfThrust 0 0 1
                        thrustConstants 1 10
                        torqueConstants 0 0
                        device RotationalMotor {
                          name "PROP_3"
                          maxTorque 100
                        }
                        fastHelix Solid {
                          children [
                            USE WHEEL
                          ]
                          boundingObject USE WHEEL
                        }
                      }
                      DEF WHEEL Shape {
                        appearance PBRAppearance {
                          baseColor 0 0 0
                          roughness 1
                          metalness 0
                        }
                        geometry Cylinder {
                          height 0.3
                          radius 2
                          subdivision 72
                        }
                      }
                    ]
                    boundingObject USE WHEEL
                    physics Physics {
                      density -1
                      mass 0.01
                      centerOfMass [
                        0 0 0
                      ]
                      inertiaMatrix [
                        0.010075 0.010075 0.02
                        0 0 0
                      ]
                      damping Damping {
                      }
                    }
                  }
                }
                DEF ARM2 Shape {
                  appearance PBRAppearance {
                    baseColor 0.333333 0 1
                    roughness 1
                    metalness 0.1
                    IBLStrength 0.5
                  }
                  geometry Box {
                    size 1.25 4 1
                  }
                }
              ]
              boundingObject USE ARM2
              physics Physics {
                density -1
                mass 0.3
                centerOfMass [
                  0 0 0
                ]
                inertiaMatrix [
                  1.0625 0.16015625 1.09765625
                  0 0 0
                ]
              }
            }
          }
          DEF ARM_1 Shape {
            appearance PBRAppearance {
              baseColor 1 0.960784 0.529412
              roughness 1
              IBLStrength 0.5
            }
            geometry DEF ARM_ Box {
              size 1 3 1
            }
          }
        ]
        name "solid(2)"
        boundingObject USE ARM_1
        physics Physics {
          density -1
          mass 0.2
          centerOfMass [
            0 0 0
          ]
          inertiaMatrix [
            2500 500 2500
            0 0 0
          ]
        }
      }
    }
    DEF HINGE_RL HingeJoint {
      jointParameters HingeJointParameters {
        position 0.0002742503010043417
        anchor 0 0.8 0.5
        minStop -2
        maxStop 2
      }
      device [
        RotationalMotor {
          name "MOTOR_RL1"
          controlPID 2 0 0.5
          maxTorque 5000
        }
      ]
      endPoint Solid {
        translation -2.5000300000000006 1.9998416412920397 1.0003798915040614
        rotation 0.9972867093243241 -0.07361534688566898 -1.0390546442717298e-05 0.0002666247731230846
        children [
          SliderJoint {
            jointParameters JointParameters {
              position 8.326582856210685e-06
              axis 0 2.3 -1.22
              minStop -75
              maxStop 1
            }
            device [
              LinearMotor {
                name "MOTOR_SRL"
                controlPID 2 0 0.5
                maxForce 5000
              }
            ]
            endPoint Solid {
              translation 0 1.733420069387286 -0.06859673245760396
              rotation 1 0 0 -0.5
              children [
                DEF PLACE_HOLDER HingeJoint {
                  jointParameters HingeJointParameters {
                    position -2.6328944358056106e-08
                    axis 0 0 1
                    anchor 0 1 1
                  }
                  device [
                    DEF WHEEL_L RotationalMotor {
                      name "WHEEL_2"
                      maxVelocity 100
                      maxTorque 100
                    }
                  ]
                  endPoint DEF WHEEL_ Solid {
                    translation 0 1 0.6500000000000001
                    rotation 0 0 1 0.13089966757063065
                    children [
                      Propeller {
                        shaftAxis 0 0 1
                        centerOfThrust 0 0 1
                        thrustConstants 1 10
                        torqueConstants 0 0
                        device RotationalMotor {
                          name "PROP_2"
                          maxTorque 100
                        }
                        fastHelix Solid {
                          children [
                            USE WHEEL
                          ]
                          boundingObject USE WHEEL
                        }
                      }
                      DEF WHEEL Shape {
                        appearance PBRAppearance {
                          baseColor 0 0 0
                          roughness 1
                          metalness 0
                        }
                        geometry Cylinder {
                          height 0.3
                          radius 2
                          subdivision 72
                        }
                      }
                    ]
                    boundingObject USE WHEEL
                    physics Physics {
                      density -1
                      mass 0.01
                      centerOfMass [
                        0 0 0
                      ]
                      inertiaMatrix [
                        0.010075 0.010075 0.02
                        0 0 0
                      ]
                      damping Damping {
                      }
                    }
                  }
                }
                DEF ARM2 Shape {
                  appearance PBRAppearance {
                    baseColor 0.333333 0 1
                    roughness 1
                    metalness 0.1
                    IBLStrength 0.5
                  }
                  geometry Box {
                    size 1.25 4 1
                  }
                }
              ]
              boundingObject USE ARM2
              physics Physics {
                density -1
                mass 0.3
                centerOfMass [
                  0 0 0
                ]
                inertiaMatrix [
                  1.0625 0.16015625 1.09765625
                  0 0 0
                ]
              }
            }
          }
          DEF ARM_1 Shape {
            appearance PBRAppearance {
              baseColor 1 0.960784 0.529412
              roughness 1
              IBLStrength 0.5
            }
            geometry DEF ARM_ Box {
              size 1 3 1
            }
          }
        ]
        name "solid(1)"
        boundingObject USE ARM_1
        physics Physics {
          density -1
          mass 0.2
          centerOfMass [
            0 0 0
          ]
          inertiaMatrix [
            2500 500 2500
            0 0 0
          ]
        }
      }
    }
    DEF HINGE_FL HingeJoint {
      jointParameters HingeJointParameters {
        position 0.00027425457554339564
        anchor 0 0.8 0.5
        minStop -2
        maxStop 2
      }
      device [
        RotationalMotor {
          name "MOTOR_FL1"
          controlPID 2 0 0.5
          maxTorque 5000
        }
      ]
      endPoint Solid {
        translation 2.499999999999981 1.9998628275845995 1.0003290866826333
        rotation 1 0 0 0.00027425457617863316
        children [
          SliderJoint {
            jointParameters JointParameters {
              position 8.326468981079138e-06
              axis 0 2.3 -1.22
              minStop -75
              maxStop 1
            }
            device [
              LinearMotor {
                name "MOTOR_SFL"
                controlPID 2 0 0.5
                maxForce 5000
              }
            ]
            endPoint Solid {
              translation 0 1.7334200692865314 -0.06859673240416005
              rotation 1 0 0 -0.5
              children [
                DEF PLACE_HOLDER HingeJoint {
                  jointParameters HingeJointParameters {
                    position -2.6328526914198846e-08
                    axis 0 0 1
                    anchor 0 1 1
                  }
                  device [
                    DEF WHEEL_L RotationalMotor {
                      name "WHEEL_1"
                      maxVelocity 100
                      maxTorque 100
                    }
                  ]
                  endPoint DEF WHEEL_ Solid {
                    translation 0 1 0.6500000000000001
                    rotation 0 0 -1 2.9802322387695313e-08
                    children [
                      Propeller {
                        shaftAxis 0 0 1
                        centerOfThrust 0 0 1
                        thrustConstants 1 10
                        torqueConstants 0 0
                        device RotationalMotor {
                          name "PROP_1"
                          maxTorque 100
                        }
                        fastHelix Solid {
                          children [
                            USE WHEEL
                          ]
                          boundingObject USE WHEEL
                        }
                      }
                      DEF WHEEL Shape {
                        appearance PBRAppearance {
                          baseColor 0 0 0
                          roughness 1
                          metalness 0
                        }
                        geometry Cylinder {
                          height 0.3
                          radius 2
                          subdivision 72
                        }
                      }
                    ]
                    boundingObject USE WHEEL
                    physics Physics {
                      density -1
                      mass 0.01
                      centerOfMass [
                        0 0 0
                      ]
                      inertiaMatrix [
                        0.010075 0.010075 0.02
                        0 0 0
                      ]
                      damping Damping {
                      }
                    }
                  }
                }
                DEF ARM2 Shape {
                  appearance PBRAppearance {
                    baseColor 0.333333 0 1
                    roughness 1
                    metalness 0.1
                    IBLStrength 0.5
                  }
                  geometry Box {
                    size 1.25 4 1
                  }
                }
              ]
              boundingObject USE ARM2
              physics Physics {
                density -1
                mass 0.3
                centerOfMass [
                  0 0 0
                ]
                inertiaMatrix [
                  1.0625 0.16015625 1.09765625
                  0 0 0
                ]
              }
            }
          }
          DEF ARM_1 Shape {
            appearance PBRAppearance {
              baseColor 1 0.960784 0.529412
              roughness 1
              IBLStrength 0.5
            }
            geometry DEF ARM_ Box {
              size 1 3 1
            }
          }
        ]
        boundingObject USE ARM_1
        physics Physics {
          density -1
          mass 0.2
          centerOfMass [
            0 0 0
          ]
          inertiaMatrix [
            2500 500 2500
            0 0 0
          ]
        }
      }
    }
    DEF BODY_ Shape {
      appearance PBRAppearance {
        baseColor 0.25098 0.392157 1
        roughness 0.7
        metalness 0.5
        IBLStrength 0.5
      }
      geometry DEF SHAPE_ Box {
        size 7 2 2
      }
    }
  ]
  name "DRONE"
  boundingObject USE BODY_
  physics Physics {
    density -1
    mass 5
    centerOfMass [
      0 0 0
    ]
    inertiaMatrix [
      6.666666666666667 44.16666666666667 44.16666666666667
      0 0 0
    ]
  }
  controller "my_controller_DRONE-27"
  controllerArgs [
    ""
  ]
}
